Workbook
Name Slicer_Attendance_Group: #N/A
Name Slicer_Gender: #N/A
Name Slicer_Performance: #N/A

Sheet Raw Data
A1: Student_ID | B1: Name | C1: Gender | D1: Study_Hours_Per_Day | E1: Attendance (%) | F1: Assignment_Score | G1: Midterm_Score | H1: Final_Exam_Score | I1: Extra_Activities | J1: Sleep_Hours | K1: Internet_Usage (hrs/day)
A2: 1 | B2: Aarav | C2: Male | D2: 3 | E2: 85 | F2: 78 | G2: 72 | H2: 80 | I2: Yes | J2: 7 | K2: 3
A3: 2 | B3: Diya | C3: Female | D3: 5 | E3: 92 | F3: 88 | G3: 85 | H3: 90 | I3: No | J3: 6 | K3: 2
A4: 3 | B4: Vihaan | C4: Male | E4: 70 | F4: 60 | G4: 58 | H4: 62 | I4: Yes | J4: 8 | K4: 5
A5: 4 | B5: Ananya | C5: Female | D5: 4 | E5: 88 | F5: 82 | G5: 79 | H5: 85 | I5: Yes | J5: 7
A6: 5 | B6: Kabir | C6: Male | D6: 6 | E6: 95 | F6: 90 | G6: 92 | H6: 94 | I6: No | J6: 6 | K6: 2
A7: 6 | B7: Isha | C7: Female | D7: 3 | E7: 80 | G7: 70 | H7: 78 | I7: Yes | J7: 7 | K7: 4
A8: 7 | B8: Rohan | C8: Male | D8: 1 | E8: 65 | F8: 55 | G8: 50 | H8: 58 | I8: No | J8: 8 | K8: 6
A9: 8 | B9: Meera | C9: Female | D9: 5 | E9: 90 | F9: 85 | G9: 87 | H9: 89 | I9: Yes | K9: 2
A10: 9 | B10: Arjun | C10: Male | D10: 4 | E10: 85 | F10: 80 | G10: 78 | H10: 82 | I10: Yes | J10: 7 | K10: 3
A11: 10 | B11: Saanvi | C11: Female | D11: 6 | E11: 96 | F11: 92 | G11: 94 | H11: 95 | I11: No | J11: 6 | K11: 2
A12: 11 | B12: Aditya | C12: Male | D12: 2 | E12: 75 | F12: 65 | G12: 60 | H12: 68 | I12: Yes | J12: 7 | K12: 5
A13: 12 | B13: Kavya | C13: Female | D13: 4 | E13: 88 | F13: 84 | G13: 82 | H13: 86 | I13: Yes | J13: 6 | K13: 3
A14: 13 | B14: Raj | C14: Male | D14: 3 | E14: 82 | F14: 78 | G14: 74 | H14: 79 | I14: No | J14: 7 | K14: 4
A15: 14 | B15: Pooja | C15: Female | D15: 5 | E15: 91 | F15: 87 | G15: 88 | H15: 90 | I15: Yes | J15: 6 | K15: 2
A16: 15 | B16: Manish | C16: Male | D16: 2 | E16: 68 | F16: 60 | H16: 65 | I16: No | J16: 8 | K16: 5
A17: 16 | B17: Neha | C17: Female | D17: 4 | E17: 86 | F17: 80 | G17: 82 | H17: 84 | I17: Yes | J17: 7 | K17: 3
A18: 17 | B18: Vikram | C18: Male | D18: 6 | E18: 94 | F18: 91 | G18: 90 | H18: 93 | I18: No | J18: 6 | K18: 2
A19: 18 | B19: Simran | C19: Female | D19: 3 | E19: 78 | F19: 72 | G19: 70 | H19: 75 | I19: Yes | J19: 7 | K19: 4
A20: 19 | B20: Karan | C20: Male | D20: 2 | E20: 72 | F20: 65 | G20: 63 | H20: 67 | I20: No | J20: 8 | K20: 5
A21: 20 | B21: Riya | C21: Female | D21: 5 | E21: 90 | F21: 86 | G21: 88 | H21: 89 | I21: Yes | J21: 6 | K21: 2
A22: 21 | B22: Aman | C22: Male | D22: 3 | E22: 80 | F22: 75 | G22: 73 | H22: 77 | I22: Yes | J22: 7 | K22: 4
A23: 22 | B23: Shreya | C23: Female | D23: 4 | E23: 87 | F23: 82 | G23: 80 | H23: 85 | I23: No | J23: 6 | K23: 3
A24: 23 | B24: Rahul | C24: Male | D24: 1 | E24: 60 | F24: 50 | G24: 48 | H24: 55 | I24: No | J24: 8 | K24: 6
A25: 24 | B25: Nisha | C25: Female | D25: 5 | E25: 92 | F25: 88 | G25: 90 | H25: 91 | I25: Yes | J25: 6 | K25: 2
A26: 25 | B26: Deepak | C26: Male | D26: 3 | E26: 78 | F26: 72 | G26: 70 | H26: 74 | I26: Yes | J26: 7 | K26: 4
A27: 26 | B27: Priya | C27: Female | D27: 6 | E27: 95 | F27: 92 | G27: 93 | H27: 96 | I27: No | J27: 6 | K27: 2
A28: 27 | B28: Sachin | C28: Male | D28: 2 | E28: 70 | F28: 62 | G28: 60 | H28: 66 | I28: Yes | J28: 8 | K28: 5
... A56: 52 | B56: ANANYA | C56: FEMALE | D56: 4 | E56: 88 | F56: 82 | G56: 79 | H56: 85 | I56: YES | J56: 7 | K56: 3
A57: 53 | C57: Female | D57: 5 | E57: 90 | F57: 85 | G57: 87 | H57: 89 | I57: Yes | J57: 6 | K57: 2
A58: 54 | B58: Rohit | C58: Male | D58: 4 | E58: 88 | F58: 82 | G58: 80 | H58: 85 | I58: Yes | J58: 7 | K58: 3
A59: 55 | B59: Ankit | C59: Male | D59: 2 | E59: 75 | F59: 65 | G59: 60 | H59: 68 | I59: No | J59: 8 | K59: 5
A60: 56 | B60: Neeraj | C60: Male | D60: 3 | E60: 80 | F60: 75 | G60: 72 | H60: 78 | I60: Yes | J60: 7 | K60: 4
A61: 57 | B61: Payal | C61: Female | D61: 5 | E61: 90 | F61: 86 | G61: 88 | H61: 91 | I61: Yes | J61: 6 | K61: 2
A62: 58 | B62: Sakshi | C62: Female | D62: 4 | E62: 85 | F62: 80 | G62: 82 | H62: 84 | I62: Yes | J62: 7 | K62: 3
A63: 59 | B63: Amit | C63: Male | D63: 1 | E63: 60 | F63: 50 | G63: 48 | H63: 55 | I63: No | J63: 8 | K63: 6
A64: 60 | B64: Ritu | C64: Female | D64: 6 | E64: 95 | F64: 92 | G64: 93 | H64: 96 | I64: No | J64: 6 | K64: 2
A65: 61 | B65: Kiran | C65: Female | D65: 3 | E65: 78 | F65: 72 | G65: 70 | H65: 75 | I65: Yes | J65: 7 | K65: 4
A66: 62 | B66: Varsha | C66: Female | E66: 82 | F66: 78 | G66: 76 | H66: 80 | I66: Yes | J66: 7 | K66: 3
A67: 63 | B67: Deep | C67: Male | D67: 2 | E67: 70 | F67: 65 | G67: 60 | H67: 66 | I67: No | J67: 8 | K67: 5
...

Sheet Clean Data
B3: Student_ID | C3: Name | D3: Gender | E3: Study_Hours_Per_Day | F3: Attendance (%) | G3: Assignment_Score | H3: Midterm_Score | I3: Final_Exam_Score | J3: Extra_Activities | K3: Sleep_Hours | L3: Internet_Usage (hrs/day) | M3: Total_Score | N3: Average_Score | O3: Performance | P3: Study_Efficiency | Q3: At_Risk | R3: Smart_Students | S3: Balanced_Student | T3: Attendance_Group | U3: Grade | AA3: Grade Table
B4: 1 | C4: Aarav | D4: Male | E4: 3 | F4: 85 | G4: 78 | H4: 72 | I4: 80 | J4: Yes | K4: 7 | L4: 3 | M4: =SUM(G4:I4) -> 230 | N4: =AVERAGE(G4:I4) -> 76.666667 | O4: =IF(N4>= 80, "Excellent",IF(N4>=60, "Good","Needs Improvement")) -> Good | P4: =IF(E4,N4/E4,0) -> 25.555556 | Q4: =IF(AND(F4 < 75,N4 < 60),"Yes", "No") -> No | R4: =IF(AND(N4>=80,E4<=2),"Smart Students","Normal Students") -> Normal Students | S4: =IF(AND(F4>=75,K4>=6,N4>=80),"Balanced Student","Unbalanced Student") -> Unbalanced Student | T4: =IF(F4>= 80, "High", IF(F4>=60,"Medium", "Low")) -> High | U4: =VLOOKUP(N4,$AA$5:$AB$9,2,1) -> B | AA4: Min Score | AB4: Grade
B5: 2 | C5: Diya | D5: Female | E5: 5 | F5: 92 | G5: 88 | H5: 85 | I5: 90 | J5: No | K5: 6 | L5: 2 | M5: =SUM(G5:I5) -> 263 | N5: =AVERAGE(G5:I5) -> 87.666667 | O5: =IF(N5>= 80, "Excellent",IF(N5>=60, "Good","Needs Improvement")) -> Excellent | P5: =IF(E5,N5/E5,0) -> 17.533333 | Q5: =IF(AND(F5 < 75,N5 < 60),"Yes", "No") -> No | R5: =IF(AND(N5>=80,E5<=2),"Smart Students","Normal Students") -> Normal Students | S5: =IF(AND(F5>=75,K5>=6,N5>=80),"Balanced Student","Unbalanced Student") -> Balanced Student | T5: =IF(F5>= 80, "High", IF(F5>=60,"Medium", "Low")) -> High | U5: ` | AA5: 0 | AB5: F
B6: 3 | C6: Vihaan | D6: Male | E6: 0 | F6: 70 | G6: 60 | H6: 58 | I6: 62 | J6: Yes | K6: 8 | L6: 5 | M6: =SUM(G6:I6) -> 180 | N6: =AVERAGE(G6:I6) -> 60 | O6: =IF(N6>= 80, "Excellent",IF(N6>=60, "Good","Needs Improvement")) -> Good | P6: =IF(E6,N6/E6,0) -> 0 | Q6: =IF(AND(F6 < 75,N6 < 60),"Yes", "No") -> No | R6: =IF(AND(N6>=80,E6<=2),"Smart Students","Normal Students") -> Normal Students | S6: =IF(AND(F6>=75,K6>=6,N6>=80),"Balanced Student","Unbalanced Student") -> Unbalanced Student | T6: =IF(F6>= 80, "High", IF(F6>=60,"Medium", "Low")) -> Medium | U6: =VLOOKUP(N6,$AA$5:$AB$9,2,1) -> C | AA6: 50 | AB6: D
B7: 4 | C7: Ananya | D7: Female | E7: 4 | F7: 88 | G7: 82 | H7: 79 | I7: 85 | J7: Yes | K7: 7 | L7: 0 | M7: =SUM(G7:I7) -> 246 | N7: =AVERAGE(G7:I7) -> 82 | O7: =IF(N7>= 80, "Excellent",IF(N7>=60, "Good","Needs Improvement")) -> Excellent | P7: =IF(E7,N7/E7,0) -> 20.5 | Q7: =IF(AND(F7 < 75,N7 < 60),"Yes", "No") -> No | R7: =IF(AND(N7>=80,E7<=2),"Smart Students","Normal Students") -> Normal Students | S7: =IF(AND(F7>=75,K7>=6,N7>=80),"Balanced Student","Unbalanced Student") -> Balanced Student | T7: =IF(F7>= 80, "High", IF(F7>=60,"Medium", "Low")) -> High | U7: =VLOOKUP(N7,$AA$5:$AB$9,2,1) -> A | AA7: 60 | AB7: C
B8: 5 | C8: Kabir | D8: Male | E8: 6 | F8: 95 | G8: 90 | H8: 92 | I8: 94 | J8: No | K8: 6 | L8: 2 | M8: =SUM(G8:I8) -> 276 | N8: =AVERAGE(G8:I8) -> 92 | O8: =IF(N8>= 80, "Excellent",IF(N8>=60, "Good","Needs Improvement")) -> Excellent | P8: =IF(E8,N8/E8,0) -> 15.333333 | Q8: =IF(AND(F8 < 75,N8 < 60),"Yes", "No") -> No | R8: =IF(AND(N8>=80,E8<=2),"Smart Students","Normal Students") -> Normal Students | S8: =IF(AND(F8>=75,K8>=6,N8>=80),"Balanced Student","Unbalanced Student") -> Balanced Student | T8: =IF(F8>= 80, "High", IF(F8>=60,"Medium", "Low")) -> High | U8: =VLOOKUP(N8,$AA$5:$AB$9,2,1) -> A | AA8: 70 | AB8: B
B9: 6 | C9: Isha | D9: Female | E9: 3 | F9: 80 | G9: 0 | H9: 70 | I9: 78 | J9: Yes | K9: 7 | L9: 4 | M9: =SUM(G9:I9) -> 148 | N9: =AVERAGE(G9:I9) -> 49.333333 | O9: =IF(N9>= 80, "Excellent",IF(N9>=60, "Good","Needs Improvement")) -> Needs Improvement | P9: =IF(E9,N9/E9,0) -> 16.444444 | Q9: =IF(AND(F9 < 75,N9 < 60),"Yes", "No") -> No | R9: =IF(AND(N9>=80,E9<=2),"Smart Students","Normal Students") -> Normal Students | S9: =IF(AND(F9>=75,K9>=6,N9>=80),"Balanced Student","Unbalanced Student") -> Unbalanced Student | T9: =IF(F9>= 80, "High", IF(F9>=60,"Medium", "Low")) -> High | U9: =VLOOKUP(N9,$AA$5:$AB$9,2,1) -> F | AA9: 80 | AB9: A
B10: 7 | C10: Rohan | D10: Male | E10: 1 | F10: 65 | G10: 85 | H10: 90 | I10: 78 | J10: No | K10: 8 | L10: 6 | M10: =SUM(G10:I10) -> 253 | N10: =AVERAGE(G10:I10) -> 84.333333 | O10: =IF(N10>= 80, "Excellent",IF(N10>=60, "Good","Needs Improvement")) -> Excellent | P10: =IF(E10,N10/E10,0) -> 84.333333 | Q10: =IF(AND(F10 < 75,N10 < 60),"Yes", "No") -> No | R10: =IF(AND(N10>=80,E10<=2),"Smart Students","Normal Students") -> Smart Students | S10: =IF(AND(F10>=75,K10>=6,N10>=80),"Balanced Student","Unbalanced Student") -> Unbalanced Student | T10: =IF(F10>= 80, "High", IF(F10>=60,"Medium", "Low")) -> Medium | U10: =VLOOKUP(N10,$AA$5:$AB$9,2,1) -> A
B11: 8 | C11: Meera | D11: Female | E11: 5 | F11: 90 | G11: 85 | H11: 87 | I11: 89 | J11: Yes | K11: 0 | L11: 2 | M11: =SUM(G11:I11) -> 261 | N11: =AVERAGE(G11:I11) -> 87 | O11: =IF(N11>= 80, "Excellent",IF(N11>=60, "Good","Needs Improvement")) -> Excellent | P11: =IF(E11,N11/E11,0) -> 17.4 | Q11: =IF(AND(F11 < 75,N11 < 60),"Yes", "No") -> No | R11: =IF(AND(N11>=80,E11<=2),"Smart Students","Normal Students") -> Normal Students | S11: =IF(AND(F11>=75,K11>=6,N11>=80),"Balanced Student","Unbalanced Student") -> Unbalanced Student | T11: =IF(F11>= 80, "High", IF(F11>=60,"Medium", "Low")) -> High | U11: =VLOOKUP(N11,$AA$5:$AB$9,2,1) -> A
B12: 9 | C12: Arjun | D12: Male | E12: 4 | F12: 85 | G12: 80 | H12: 78 | I12: 82 | J12: Yes | K12: 7 | L12: 3 | M12: =SUM(G12:I12) -> 240 | N12: =AVERAGE(G12:I12) -> 80 | O12: =IF(N12>= 80, "Excellent",IF(N12>=60, "Good","Needs Improvement")) -> Excellent | P12: =IF(E12,N12/E12,0) -> 20 | Q12: =IF(AND(F12 < 75,N12 < 60),"Yes", "No") -> No | R12: =IF(AND(N12>=80,E12<=2),"Smart Students","Normal Students") -> Normal Students | S12: =IF(AND(F12>=75,K12>=6,N12>=80),"Balanced Student","Unbalanced Student") -> Balanced Student | T12: =IF(F12>= 80, "High", IF(F12>=60,"Medium", "Low")) -> High | U12: =VLOOKUP(N12,$AA$5:$AB$9,2,1) -> A | AA12: summary(Study Hours Analysis)
B13: 10 | C13: Saanvi | D13: Female | E13: 6 | F13: 96 | G13: 72 | H13: 94 | I13: 95 | J13: No | K13: 6 | L13: 2 | M13: =SUM(G13:I13) -> 261 | N13: =AVERAGE(G13:I13) -> 87 | O13: =IF(N13>= 80, "Excellent",IF(N13>=60, "Good","Needs Improvement")) -> Excellent | P13: =IF(E13,N13/E13,0) -> 14.5 | Q13: =IF(AND(F13 < 75,N13 < 60),"Yes", "No") -> No | R13: =IF(AND(N13>=80,E13<=2),"Smart Students","Normal Students") -> Normal Students | S13: =IF(AND(F13>=75,K13>=6,N13>=80),"Balanced Student","Unbalanced Student") -> Balanced Student | T13: =IF(F13>= 80, "High", IF(F13>=60,"Medium", "Low")) -> High | U13: =VLOOKUP(N13,$AA$5:$AB$9,2,1) -> A | AA13: Average Study Hours | AB13: =AVERAGE(E4:E503) -> 3.608
B14: 11 | C14: Aditya | D14: Male | E14: 2 | F14: 75 | G14: 65 | H14: 60 | I14: 68 | J14: Yes | K14: 7 | L14: 5 | M14: =SUM(G14:I14) -> 193 | N14: =AVERAGE(G14:I14) -> 64.333333 | O14: =IF(N14>= 80, "Excellent",IF(N14>=60, "Good","Needs Improvement")) -> Good | P14: =IF(E14,N14/E14,0) -> 32.166667 | Q14: =IF(AND(F14 < 75,N14 < 60),"Yes", "No") -> No | R14: =IF(AND(N14>=80,E14<=2),"Smart Students","Normal Students") -> Normal Students | S14: =IF(AND(F14>=75,K14>=6,N14>=80),"Balanced Student","Unbalanced Student") -> Unbalanced Student | T14: =IF(F14>= 80, "High", IF(F14>=60,"Medium", "Low")) -> Medium | U14: =VLOOKUP(N14,$AA$5:$AB$9,2,1) -> C | AA14: Median Study Hours | AB14: =MEDIAN(E4:E503) -> 4
B15: 12 | C15: Kavya | D15: Female | E15: 4 | F15: 88 | G15: 84 | H15: 82 | I15: 86 | J15: Yes | K15: 6 | L15: 3 | M15: =SUM(G15:I15) -> 252 | N15: =AVERAGE(G15:I15) -> 84 | O15: =IF(N15>= 80, "Excellent",IF(N15>=60, "Good","Needs Improvement")) -> Excellent | P15: =IF(E15,N15/E15,0) -> 21 | Q15: =IF(AND(F15 < 75,N15 < 60),"Yes", "No") -> No | R15: =IF(AND(N15>=80,E15<=2),"Smart Students","Normal Students") -> Normal Students | S15: =IF(AND(F15>=75,K15>=6,N15>=80),"Balanced Student","Unbalanced Student") -> Balanced Student | T15: =IF(F15>= 80, "High", IF(F15>=60,"Medium", "Low")) -> High | U15: =VLOOKUP(N15,$AA$5:$AB$9,2,1) -> A | AA15: Most common Study Hours (Mode) | AB15: =MODE(E4:E503) -> 3
B16: 13 | C16: Raj | D16: Male | E16: 3 | F16: 82 | G16: 78 | H16: 74 | I16: 79 | J16: No | K16: 7 | L16: 4 | M16: =SUM(G16:I16) -> 231 | N16: =AVERAGE(G16:I16) -> 77 | O16: =IF(N16>= 80, "Excellent",IF(N16>=60, "Good","Needs Improvement")) -> Good | P16: =IF(E16,N16/E16,0) -> 25.666667 | Q16: =IF(AND(F16 < 75,N16 < 60),"Yes", "No") -> No | R16: =IF(AND(N16>=80,E16<=2),"Smart Students","Normal Students") -> Normal Students | S16: =IF(AND(F16>=75,K16>=6,N16>=80),"Balanced Student","Unbalanced Student") -> Unbalanced Student | T16: =IF(F16>= 80, "High", IF(F16>=60,"Medium", "Low")) -> High | U16: =VLOOKUP(N16,$AA$5:$AB$9,2,1) -> B | AA16: Standard Deviation | AB16: =STDEV(E4:E503) -> 1.4235128
B17: 14 | C17: Pooja | D17: Female | E17: 5 | F17: 91 | G17: 87 | H17: 88 | I17: 90 | J17: Yes | K17: 6 | L17: 2 | M17: =SUM(G17:I17) -> 265 | N17: =AVERAGE(G17:I17) -> 88.333333 | O17: =IF(N17>= 80, "Excellent",IF(N17>=60, "Good","Needs Improvement")) -> Excellent | P17: =IF(E17,N17/E17,0) -> 17.666667 | Q17: =IF(AND(F17 < 75,N17 < 60),"Yes", "No") -> No | R17: =IF(AND(N17>=80,E17<=2),"Smart Students","Normal Students") -> Normal Students | S17: =IF(AND(F17>=75,K17>=6,N17>=80),"Balanced Student","Unbalanced Student") -> Balanced Student | T17: =IF(F17>= 80, "High", IF(F17>=60,"Medium", "Low")) -> High | U17: =VLOOKUP(N17,$AA$5:$AB$9,2,1) -> A
B18: 15 | C18: Manish | D18: Male | E18: 2 | F18: 68 | G18: 60 | H18: 0 | I18: 65 | J18: No | K18: 8 | L18: 5 | M18: =SUM(G18:I18) -> 125 | N18: =AVERAGE(G18:I18) -> 41.666667 | O18: =IF(N18>= 80, "Excellent",IF(N18>=60, "Good","Needs Improvement")) -> Needs Improvement | P18: =IF(E18,N18/E18,0) -> 20.833333 | Q18: =IF(AND(F18 < 75,N18 < 60),"Yes", "No") -> Yes | R18: =IF(AND(N18>=80,E18<=2),"Smart Students","Normal Students") -> Normal Students | S18: =IF(AND(F18>=75,K18>=6,N18>=80),"Balanced Student","Unbalanced Student") -> Unbalanced Student | T18: =IF(F18>= 80, "High", IF(F18>=60,"Medium", "Low")) -> Medium | U18: =VLOOKUP(N18,$AA$5:$AB$9,2,1) -> F | AA18: summary(Score Analysis)
B19: 16 | C19: Neha | D19: Female | E19: 4 | F19: 86 | G19: 80 | H19: 82 | I19: 84 | J19: Yes | K19: 7 | L19: 3 | M19: =SUM(G19:I19) -> 246 | N19: =AVERAGE(G19:I19) -> 82 | O19: =IF(N19>= 80, "Excellent",IF(N19>=60, "Good","Needs Improvement")) -> Excellent | P19: =IF(E19,N19/E19,0) -> 20.5 | Q19: =IF(AND(F19 < 75,N19 < 60),"Yes", "No") -> No | R19: =IF(AND(N19>=80,E19<=2),"Smart Students","Normal Students") -> Normal Students | S19: =IF(AND(F19>=75,K19>=6,N19>=80),"Balanced Student","Unbalanced Student") -> Balanced Student | T19: =IF(F19>= 80, "High", IF(F19>=60,"Medium", "Low")) -> High | U19: =VLOOKUP(N19,$AA$5:$AB$9,2,1) -> A | AA19: Mean score | AB19: =AVERAGE(M4:M503) -> 233.716
B20: 17 | C20: Vikram | D20: Male | E20: 6 | F20: 94 | G20: 91 | H20: 90 | I20: 93 | J20: No | K20: 6 | L20: 2 | M20: =SUM(G20:I20) -> 274 | N20: =AVERAGE(G20:I20) -> 91.333333 | O20: =IF(N20>= 80, "Excellent",IF(N20>=60, "Good","Needs Improvement")) -> Excellent | P20: =IF(E20,N20/E20,0) -> 15.222222 | Q20: =IF(AND(F20 < 75,N20 < 60),"Yes", "No") -> No | R20: =IF(AND(N20>=80,E20<=2),"Smart Students","Normal Students") -> Normal Students | S20: =IF(AND(F20>=75,K20>=6,N20>=80),"Balanced Student","Unbalanced Student") -> Balanced Student | T20: =IF(F20>= 80, "High", IF(F20>=60,"Medium", "Low")) -> High | U20: =VLOOKUP(N20,$AA$5:$AB$9,2,1) -> A | AA20: Median score | AB20: =MEDIAN(M4:M503) -> 246
B21: 18 | C21: Simran | D21: Female | E21: 3 | F21: 78 | G21: 72 | H21: 70 | I21: 75 | J21: Yes | K21: 7 | L21: 4 | M21: =SUM(G21:I21) -> 217 | N21: =AVERAGE(G21:I21) -> 72.333333 | O21: =IF(N21>= 80, "Excellent",IF(N21>=60, "Good","Needs Improvement")) -> Good | P21: =IF(E21,N21/E21,0) -> 24.111111 | Q21: =IF(AND(F21 < 75,N21 < 60),"Yes", "No") -> No | R21: =IF(AND(N21>=80,E21<=2),"Smart Students","Normal Students") -> Normal Students | S21: =IF(AND(F21>=75,K21>=6,N21>=80),"Balanced Student","Unbalanced Student") -> Unbalanced Student | T21: =IF(F21>= 80, "High", IF(F21>=60,"Medium", "Low")) -> Medium | U21: =VLOOKUP(N21,$AA$5:$AB$9,2,1) -> B | AA21: Mode | AB21: =MODE(M4:M503) -> 246
B22: 19 | C22: Karan | D22: Male | E22: 2 | F22: 72 | G22: 65 | H22: 63 | I22: 67 | J22: No | K22: 8 | L22: 5 | M22: =SUM(G22:I22) -> 195 | N22: =AVERAGE(G22:I22) -> 65 | O22: =IF(N22>= 80, "Excellent",IF(N22>=60, "Good","Needs Improvement")) -> Good | P22: =IF(E22,N22/E22,0) -> 32.5 | Q22: =IF(AND(F22 < 75,N22 < 60),"Yes", "No") -> No | R22: =IF(AND(N22>=80,E22<=2),"Smart Students","Normal Students") -> Normal Students | S22: =IF(AND(F22>=75,K22>=6,N22>=80),"Balanced Student","Unbalanced Student") -> Unbalanced Student | T22: =IF(F22>= 80, "High", IF(F22>=60,"Medium", "Low")) -> Medium | U22: =VLOOKUP(N22,$AA$5:$AB$9,2,1) -> C | AA22: Standard deviation | AB22: =STDEV(M4:M503) -> 32.78703
B23: 20 | C23: Riya | D23: Female | E23: 5 | F23: 90 | G23: 86 | H23: 88 | I23: 89 | J23: Yes | K23: 6 | L23: 2 | M23: =SUM(G23:I23) -> 263 | N23: =AVERAGE(G23:I23) -> 87.666667 | O23: =IF(N23>= 80, "Excellent",IF(N23>=60, "Good","Needs Improvement")) -> Excellent | P23: =IF(E23,N23/E23,0) -> 17.533333 | Q23: =IF(AND(F23 < 75,N23 < 60),"Yes", "No") -> No | R23: =IF(AND(N23>=80,E23<=2),"Smart Students","Normal Students") -> Normal Students | S23: =IF(AND(F23>=75,K23>=6,N23>=80),"Balanced Student","Unbalanced Student") -> Balanced Student | T23: =IF(F23>= 80, "High", IF(F23>=60,"Medium", "Low")) -> High | U23: =VLOOKUP(N23,$AA$5:$AB$9,2,1) -> A
B24: 21 | C24: Aman | D24: Male | E24: 3 | F24: 80 | G24: 75 | H24: 73 | I24: 77 | J24: Yes | K24: 7 | L24: 4 | M24: =SUM(G24:I24) -> 225 | N24: =AVERAGE(G24:I24) -> 75 | O24: =IF(N24>= 80, "Excellent",IF(N24>=60, "Good","Needs Improvement")) -> Good | P24: =IF(E24,N24/E24,0) -> 25 | Q24: =IF(AND(F24 < 75,N24 < 60),"Yes", "No") -> No | R24: =IF(AND(N24>=80,E24<=2),"Smart Students","Normal Students") -> Normal Students | S24: =IF(AND(F24>=75,K24>=6,N24>=80),"Balanced Student","Unbalanced Student") -> Unbalanced Student | T24: =IF(F24>= 80, "High", IF(F24>=60,"Medium", "Low")) -> High | U24: =VLOOKUP(N24,$AA$5:$AB$9,2,1) -> B
B25: 22 | C25: Shreya | D25: Female | E25: 4 | F25: 87 | G25: 82 | H25: 80 | I25: 85 | J25: No | K25: 6 | L25: 3 | M25: =SUM(G25:I25) -> 247 | N25: =AVERAGE(G25:I25) -> 82.333333 | O25: =IF(N25>= 80, "Excellent",IF(N25>=60, "Good","Needs Improvement")) -> Excellent | P25: =IF(E25,N25/E25,0) -> 20.583333 | Q25: =IF(AND(F25 < 75,N25 < 60),"Yes", "No") -> No | R25: =IF(AND(N25>=80,E25<=2),"Smart Students","Normal Students") -> Normal Students | S25: =IF(AND(F25>=75,K25>=6,N25>=80),"Balanced Student","Unbalanced Student") -> Balanced Student | T25: =IF(F25>= 80, "High", IF(F25>=60,"Medium", "Low")) -> High | U25: =VLOOKUP(N25,$AA$5:$AB$9,2,1) -> A
B26: 23 | C26: Rahul | D26: Male | E26: 1 | F26: 60 | G26: 50 | H26: 48 | I26: 55 | J26: No | K26: 8 | L26: 6 | M26: =SUM(G26:I26) -> 153 | N26: =AVERAGE(G26:I26) -> 51 | O26: =IF(N26>= 80, "Excellent",IF(N26>=60, "Good","Needs Improvement")) -> Needs Improvement | P26: =IF(E26,N26/E26,0) -> 51 | Q26: =IF(AND(F26 < 75,N26 < 60),"Yes", "No") -> Yes | R26: =IF(AND(N26>=80,E26<=2),"Smart Students","Normal Students") -> Normal Students | S26: =IF(AND(F26>=75,K26>=6,N26>=80),"Balanced Student","Unbalanced Student") -> Unbalanced Student | T26: =IF(F26>= 80, "High", IF(F26>=60,"Medium", "Low")) -> Medium | U26: =VLOOKUP(N26,$AA$5:$AB$9,2,1) -> D
B27: 24 | C27: Nisha | D27: Female | E27: 5 | F27: 92 | G27: 88 | H27: 90 | I27: 91 | J27: Yes | K27: 6 | L27: 2 | M27: =SUM(G27:I27) -> 269 | N27: =AVERAGE(G27:I27) -> 89.666667 | O27: =IF(N27>= 80, "Excellent",IF(N27>=60, "Good","Needs Improvement")) -> Excellent | P27: =IF(E27,N27/E27,0) -> 17.933333 | Q27: =IF(AND(F27 < 75,N27 < 60),"Yes", "No") -> No | R27: =IF(AND(N27>=80,E27<=2),"Smart Students","Normal Students") -> Normal Students | S27: =IF(AND(F27>=75,K27>=6,N27>=80),"Balanced Student","Unbalanced Student") -> Balanced Student | T27: =IF(F27>= 80, "High", IF(F27>=60,"Medium", "Low")) -> High | U27: =VLOOKUP(N27,$AA$5:$AB$9,2,1) -> A
B28: 25 | C28: Deepak | D28: Male | E28: 3 | F28: 78 | G28: 72 | H28: 70 | I28: 74 | J28: Yes | K28: 7 | L28: 4 | M28: =SUM(G28:I28) -> 216 | N28: =AVERAGE(G28:I28) -> 72 | O28: =IF(N28>= 80, "Excellent",IF(N28>=60, "Good","Needs Improvement")) -> Good | P28: =IF(E28,N28/E28,0) -> 24 | Q28: =IF(AND(F28 < 75,N28 < 60),"Yes", "No") -> No | R28: =IF(AND(N28>=80,E28<=2),"Smart Students","Normal Students") -> Normal Students | S28: =IF(AND(F28>=75,K28>=6,N28>=80),"Balanced Student","Unbalanced Student") -> Unbalanced Student | T28: =IF(F28>= 80, "High", IF(F28>=60,"Medium", "Low")) -> Medium | U28: =VLOOKUP(N28,$AA$5:$AB$9,2,1) -> B
B29: 26 | C29: Priya | D29: Female | E29: 6 | F29: 95 | G29: 92 | H29: 93 | I29: 96 | J29: No | K29: 6 | L29: 2 | M29: =SUM(G29:I29) -> 281 | N29: =AVERAGE(G29:I29) -> 93.666667 | O29: =IF(N29>= 80, "Excellent",IF(N29>=60, "Good","Needs Improvement")) -> Excellent | P29: =IF(E29,N29/E29,0) -> 15.611111 | Q29: =IF(AND(F29 < 75,N29 < 60),"Yes", "No") -> No | R29: =IF(AND(N29>=80,E29<=2),"Smart Students","Normal Students") -> Normal Students | S29: =IF(AND(F29>=75,K29>=6,N29>=80),"Balanced Student","Unbalanced Student") -> Balanced Student | T29: =IF(F29>= 80, "High", IF(F29>=60,"Medium", "Low")) -> High | U29: =VLOOKUP(N29,$AA$5:$AB$9,2,1) -> A
B30: 27 | C30: Sachin | D30: Male | E30: 2 | F30: 50 | G30: 62 | H30: 60 | I30: 66 | J30: Yes | K30: 8 | L30: 5 | M30: =SUM(G30:I30) -> 188 | N30: =AVERAGE(G30:I30) -> 62.666667 | O30: =IF(N30>= 80, "Excellent",IF(N30>=60, "Good","Needs Improvement")) -> Good | P30: =IF(E30,N30/E30,0) -> 31.333333 | Q30: =IF(AND(F30 < 75,N30 < 60),"Yes", "No") -> No | R30: =IF(AND(N30>=80,E30<=2),"Smart Students","Normal Students") -> Normal Students | S30: =IF(AND(F30>=75,K30>=6,N30>=80),"Balanced Student","Unbalanced Student") -> Unbalanced Student | T30: =IF(F30>= 80, "High", IF(F30>=60,"Medium", "Low")) -> Low | U30: =VLOOKUP(N30,$AA$5:$AB$9,2,1) -> C
B31: 28 | C31: Tanya | D31: Female | E31: 4 | F31: 88 | G31: 84 | H31: 83 | I31: 87 | J31: Yes | K31: 7 | L31: 3 | M31: =SUM(G31:I31) -> 254 | N31: =AVERAGE(G31:I31) -> 84.666667 | O31: =IF(N31>= 80, "Excellent",IF(N31>=60, "Good","Needs Improvement")) -> Excellent | P31: =IF(E31,N31/E31,0) -> 21.166667 | Q31: =IF(AND(F31 < 75,N31 < 60),"Yes", "No") -> No | R31: =IF(AND(N31>=80,E31<=2),"Smart Students","Normal Students") -> Normal Students | S31: =IF(AND(F31>=75,K31>=6,N31>=80),"Balanced Student","Unbalanced Student") -> Balanced Student | T31: =IF(F31>= 80, "High", IF(F31>=60,"Medium", "Low")) -> High | U31: =VLOOKUP(N31,$AA$5:$AB$9,2,1) -> A
B32: 29 | C32: Mohit | D32: Male | E32: 3 | F32: 82 | G32: 76 | H32: 75 | I32: 80 | J32: No | K32: 7 | L32: 4 | M32: =SUM(G32:I32) -> 231 | N32: =AVERAGE(G32:I32) -> 77 | O32: =IF(N32>= 80, "Excellent",IF(N32>=60, "Good","Needs Improvement")) -> Good | P32: =IF(E32,N32/E32,0) -> 25.666667 | Q32: =IF(AND(F32 < 75,N32 < 60),"Yes", "No") -> No | R32: =IF(AND(N32>=80,E32<=2),"Smart Students","Normal Students") -> Normal Students | S32: =IF(AND(F32>=75,K32>=6,N32>=80),"Balanced Student","Unbalanced Student") -> Unbalanced Student | T32: =IF(F32>= 80, "High", IF(F32>=60,"Medium", "Low")) -> High | U32: =VLOOKUP(N32,$AA$5:$AB$9,2,1) -> B
B33: 30 | C33: Alisha | D33: Female | E33: 5 | F33: 91 | G33: 87 | H33: 88 | I33: 90 | J33: Yes | K33: 6 | L33: 2 | M33: =SUM(G33:I33) -> 265 | N33: =AVERAGE(G33:I33) -> 88.333333 | O33: =IF(N33>= 80, "Excellent",IF(N33>=60, "Good","Needs Improvement")) -> Excellent | P33: =IF(E33,N33/E33,0) -> 17.666667 | Q33: =IF(AND(F33 < 75,N33 < 60),"Yes", "No") -> No | R33: =IF(AND(N33>=80,E33<=2),"Smart Students","Normal Students") -> Normal Students | S33: =IF(AND(F33>=75,K33>=6,N33>=80),"Balanced Student","Unbalanced Student") -> Balanced Student | T33: =IF(F33>= 80, "High", IF(F33>=60,"Medium", "Low")) -> High | U33: =VLOOKUP(N33,$AA$5:$AB$9,2,1) -> A
B34: 31 | C34: Ravi | D34: Male | E34: 2 | F34: 68 | G34: 60 | H34: 58 | I34: 63 | J34: No | K34: 8 | L34: 5 | M34: =SUM(G34:I34) -> 181 | N34: =AVERAGE(G34:I34) -> 60.333333 | O34: =IF(N34>= 80, "Excellent",IF(N34>=60, "Good","Needs Improvement")) -> Good | P34: =IF(E34,N34/E34,0) -> 30.166667 | Q34: =IF(AND(F34 < 75,N34 < 60),"Yes", "No") -> No | R34: =IF(AND(N34>=80,E34<=2),"Smart Students","Normal Students") -> Normal Students | S34: =IF(AND(F34>=75,K34>=6,N34>=80),"Balanced Student","Unbalanced Student") -> Unbalanced Student | T34: =IF(F34>= 80, "High", IF(F34>=60,"Medium", "Low")) -> Medium | U34: =VLOOKUP(N34,$AA$5:$AB$9,2,1) -> C
... B503: 500 | C503: Pooja | D503: Female | E503: 4 | F503: 85 | G503: 80 | H503: 82 | I503: 84 | J503: Yes | K503: 7 | L503: 3 | M503: =SUM(G503:I503) -> 246 | N503: =AVERAGE(G503:I503) -> 82 | O503: =IF(N503>= 80, "Excellent",IF(N503>=60, "Good","Needs Improvement")) -> Excellent | P503: =IF(E503,N503/E503,0) -> 20.5 | Q503: =IF(AND(F503 < 75,N503 < 60),"Yes", "No") -> No | R503: =IF(AND(N503>=80,E503<=2),"Smart Students","Normal Students") -> Normal Students | S503: =IF(AND(F503>=75,K503>=6,N503>=80),"Balanced Student","Unbalanced Student") -> Balanced Student | T503: =IF(F503>= 80, "High", IF(F503>=60,"Medium", "Low")) -> High | U503: =VLOOKUP(N503,$AA$5:$AB$9,2,1) -> A

Sheet Sheet2
A1: Student_ID | B1: Name | C1: Gender | D1: Study_Hours_Per_Day | E1: Attendance (%) | F1: Assignment_Score | G1: Midterm_Score | H1: Final_Exam_Score | I1: Extra_Activities | J1: Sleep_Hours | K1: Internet_Usage (hrs/day) | L1: Total_Score | M1: Average_Score | N1: Performance | O1: Study_Efficiency | P1: At_Risk | Q1: Smart_Students | R1: Balanced_Student | S1: Attendance_Group | T1: Grade
A2: 2 | B2: Diya | C2: Female | D2: 5 | E2: 92 | F2: 88 | G2: 85 | H2: 90 | I2: No | J2: 6 | K2: 2 | L2: 263 | M2: 87.666667 | N2: Excellent | O2: 17.533333 | P2: No | Q2: Normal Students | R2: Balanced Student | S2: High | T2: A
A3: 4 | B3: Ananya | C3: Female | D3: 4 | E3: 88 | F3: 82 | G3: 79 | H3: 85 | I3: Yes | J3: 7 | K3: 0 | L3: 246 | M3: 82 | N3: Excellent | O3: 20.5 | P3: No | Q3: Normal Students | R3: Balanced Student | S3: High | T3: A
A4: 5 | B4: Kabir | C4: Male | D4: 6 | E4: 95 | F4: 90 | G4: 92 | H4: 94 | I4: No | J4: 6 | K4: 2 | L4: 276 | M4: 92 | N4: Excellent | O4: 15.333333 | P4: No | Q4: Normal Students | R4: Balanced Student | S4: High | T4: A
A5: 7 | B5: Rohan | C5: Male | D5: 1 | E5: 65 | F5: 85 | G5: 90 | H5: 78 | I5: No | J5: 8 | K5: 6 | L5: 253 | M5: 84.333333 | N5: Excellent | O5: 84.333333 | P5: No | Q5: Smart Students | R5: Unbalanced Student | S5: Medium | T5: A
A6: 8 | B6: Meera | C6: Female | D6: 5 | E6: 90 | F6: 85 | G6: 87 | H6: 89 | I6: Yes | J6: 0 | K6: 2 | L6: 261 | M6: 87 | N6: Excellent | O6: 17.4 | P6: No | Q6: Normal Students | R6: Unbalanced Student | S6: High | T6: A
A7: 9 | B7: Arjun | C7: Male | D7: 4 | E7: 85 | F7: 80 | G7: 78 | H7: 82 | I7: Yes | J7: 7 | K7: 3 | L7: 240 | M7: 80 | N7: Excellent | O7: 20 | P7: No | Q7: Normal Students | R7: Balanced Student | S7: High | T7: A
A8: 10 | B8: Saanvi | C8: Female | D8: 6 | E8: 96 | F8: 92 | G8: 94 | H8: 95 | I8: No | J8: 6 | K8: 2 | L8: 281 | M8: 93.666667 | N8: Excellent | O8: 15.611111 | P8: No | Q8: Normal Students | R8: Balanced Student | S8: High | T8: A
A9: 12 | B9: Kavya | C9: Female | D9: 4 | E9: 88 | F9: 84 | G9: 82 | H9: 86 | I9: Yes | J9: 6 | K9: 3 | L9: 252 | M9: 84 | N9: Excellent | O9: 21 | P9: No | Q9: Normal Students | R9: Balanced Student | S9: High | T9: A
A10: 14 | B10: Pooja | C10: Female | D10: 5 | E10: 91 | F10: 87 | G10: 88 | H10: 90 | I10: Yes | J10: 6 | K10: 2 | L10: 265 | M10: 88.333333 | N10: Excellent | O10: 17.666667 | P10: No | Q10: Normal Students | R10: Balanced Student | S10: High | T10: A
A11: 16 | B11: Neha | C11: Female | D11: 4 | E11: 86 | F11: 80 | G11: 82 | H11: 84 | I11: Yes | J11: 7 | K11: 3 | L11: 246 | M11: 82 | N11: Excellent | O11: 20.5 | P11: No | Q11: Normal Students | R11: Balanced Student | S11: High | T11: A
A12: 17 | B12: Vikram | C12: Male | D12: 6 | E12: 94 | F12: 91 | G12: 90 | H12: 93 | I12: No | J12: 6 | K12: 2 | L12: 274 | M12: 91.333333 | N12: Excellent | O12: 15.222222 | P12: No | Q12: Normal Students | R12: Balanced Student | S12: High | T12: A
A13: 20 | B13: Riya | C13: Female | D13: 5 | E13: 90 | F13: 86 | G13: 88 | H13: 89 | I13: Yes | J13: 6 | K13: 2 | L13: 263 | M13: 87.666667 | N13: Excellent | O13: 17.533333 | P13: No | Q13: Normal Students | R13: Balanced Student | S13: High | T13: A
... A501: 448 | B501: Varun | C501: Male | D501: 1 | E501: 62 | F501: 52 | G501: 50 | H501: 57 | I501: No | J501: 8 | K501: 6 | L501: 159 | M501: 53 | N501: Needs Improvement | O501: 53 | P501: Yes | Q501: Normal Students | R501: Unbalanced Student | S501: Medium | T501: D

Sheet Pivot Analysis
B2: Row Labels | C2: Average of Average_Score | F2: Count of Student_ID | G2: Column Labels
B3: Female | C3: 83.228997 | F3: Row Labels | G3: Excellent | H3: Good | I3: Needs Improvement | J3: Grand Total
B4: Male | C4: 72.76378 | F4: Female | G4: 201 | H4: 42 | I4: 3 | J4: 246
B5: Grand Total | C5: 77.912667 | F5: Male | G5: 65 | H5: 175 | I5: 14 | J5: 254
B6: Average Score by Gender | F6: Grand Total | G6: 266 | H6: 217 | I6: 17 | J6: 500
F7: Performance Distribution by Gender
B11: Row Labels | C11: Average of Average_Score | F11: Row Labels | G11: Count of Student_ID
B12: High | C12: 84.515337 | F12: Excellent | G12: 266
B13: Medium | C13: 65.558767 | F13: Good | G13: 217
B14: Low | C14: 62.666667 | F14: Needs Improvement | G14: 17
B15: Grand Total | C15: 77.912667 | F15: Grand Total | G15: 500
B16: Average Score by Attendance Group | F16: Performance Category Distribution

Sheet Final Dashboard
J1: =AVERAGE('Clean Data'!N4:N503) -> 77.905333
G7: =AVERAGE('Clean Data'!N4:N503) -> 77.905333
J9: =AVERAGE('Clean Data'!N4:N503) -> 77.905333

Sheet Sheet1
B2: Average Score | C2: =AVERAGE('Clean Data'!N4:N503) -> 77.905333
B3: Total Students | C3: =COUNTA('Clean Data'!C4:C503) -> 500
B4: Max Score | C4: =MAX('Clean Data'!M4:M503) -> 284
B5: At-Risk Count | C5: =COUNTIF('Clean Data'!Q4:Q503,"Yes") -> 14

Sheet Student Performance Visual Anal
